Workbook

Sheet README
A1: Sheet | B1: Purpose
A2: Contacts | B2: One row per person. Stores segment and contact preferences.
A3: Accounts | B3: Schools, hospitals, agencies, employers, agent networks, or partner organizations.
A4: Properties | B4: One row per building / portfolio / house. This is what you need for vacancy and occupancy reporting.
A5: Units | B5: One row per rentable unit. This is what you need to show studio/1BR/2BR demand, occupancy, and pricing.
A6: Listings | B6: One row per unit-platform listing period. This is what you need to measure Zillow, Apartments.com, Realtor, MLS, etc.
A7: Campaigns | B7: Email, paid ads, listing pushes, and partner outreach campaigns.
A8: Leads | B8: One row per inquiry / opportunity. References contact, account, unit, listing, and campaign.
A9: Activities | B9: Every touchpoint. Best place to track follow-up timing and pipeline drop-off.
A10: Leases | B10: Closed deals. Best place to tie lead conversion to actual occupancy and revenue.
A11: Data Disclaimer | B11: This dataset is simulated and does not contain real customer or company data. The CRM structure, workflows, KPIs, and analysis are based on real-world experience managing leasing operations, lead conversion, and marketing performance. This project demonstrates how I would design and analyze a CRM system to support business decisions using modern data analytics techniques.

Sheet Contacts
A1: customer_id | B1: name | C1: email | D1: phone | E1: state | F1: customer_segment | G1: primary_segment_flag | H1: contact_role | I1: preferred_contact_method
A2: C-00001 | B2: Layla Young | C2: layla.young1@tufts.edu | D2: (617) 425-8359 | E2: MA | F2: Tufts Medical School | G2: Yes | H2: Relocation Coordinator | I2: Email
A3: C-00002 | B3: Benjamin Davis | C3: benjamin.davis2@gmail.com | D3: (617) 977-3615 | E3: MA | F3: Tufts Medical School | G3: Yes | H3: Prospective Tenant | I3: Email
A4: C-00003 | B4: Layla Harris | C4: layla.harris3@icloud.com | D4: (617) 484-3547 | E4: NJ | F4: Tufts Medical School | G4: Yes | H4: Prospective Tenant | I4: Text
A5: C-00004 | B5: Isabella Adams | C5: isabella.adams4@icloud.com | D5: (617) 304-2519 | E5: RI | F5: Tufts Dental School | G5: Yes | H5: Prospective Tenant | I5: Text
A6: C-00005 | B6: Ethan Garcia | C6: ethan.garcia5@icloud.com | D6: (617) 552-5333 | E6: MA | F6: Working Professional | G6: Yes | H6: Prospective Tenant | I6: Email
A7: C-00006 | B7: Jasmine Patel | C7: jasmine.patel6@yahoo.com | D7: (617) 670-9785 | E7: MA | F7: Tufts Dental School | G7: Yes | H7: Prospective Tenant | I7: Email
A8: C-00007 | B8: Charlotte Jackson | C8: charlotte.jackson7@gmail.com | D8: (617) 765-5803 | E8: PA | F8: Tufts Dental School | G8: Yes | H8: Prospective Tenant | I8: Email
A9: C-00008 | B9: Priya Lopez | C9: priya.lopez8@student.nesl.edu | D9: (617) 570-4150 | E9: PA | F9: Tufts Medical School | G9: Yes | H9: Relocation Coordinator | I9: Email
A10: C-00009 | B10: Layla Nguyen | C10: layla.nguyen9@gmail.com | D10: (617) 877-4733 | E10: CT | F10: Working Professional | G10: Yes | H10: Agent | I10: Text
A11: C-00010 | B11: Leah Wilson | C11: leah.wilson10@gmail.com | D11: (617) 438-2654 | E11: NY | F11: Graduate Student | G11: Yes | H11: Prospective Tenant | I11: Email
A12: C-00011 | B12: Ethan Davis | C12: ethan.davis11@tufts.edu | D12: (617) 850-6977 | E12: MA | F12: Graduate Student | G12: Yes | H12: Guarantor | I12: Email
... A461: C-00460 | B461: Isabella Nelson | C461: isabella.nelson460@outlook.com | D461: (617) 442-9094 | E461: PA | F461: Tufts Dental School | G461: Yes | H461: Prospective Tenant | I461: Email

Sheet Accounts
A1: account_id | B1: account_name | C1: account_type | D1: relationship_type | E1: notes
A2: A-0001 | B2: Tufts Medical School | C2: School | D2: Primary Demand Source | E2: Core student segment near Chinatown
A3: A-0002 | B3: Tufts School of Dental Medicine | C3: School | D3: Primary Demand Source | E3: Core student segment near Chinatown
A4: A-0003 | B4: New England School of Law | Boston | C4: School | D4: Primary Demand Source | E4: Secondary but local student demand
A5: A-0004 | B5: Northeastern University | C5: School | D5: Non-target / Overflow | E5: Distance lowered conversion rate
A6: A-0005 | B6: Boston University | C6: School | D6: Non-target / Overflow | E6: Distance lowered conversion rate
A7: A-0006 | B7: Suffolk University | C7: School | D7: Non-target / Overflow | E7: Occasional downtown demand
A8: A-0007 | B8: Tufts Medical Center | C8: Hospital | D8: Partner / Overflow Housing | E8: Hospital overflow referrals
A9: A-0008 | B9: Mass General Brigham | C9: Hospital | D9: Partner / Overflow Housing | E9: Hospital overflow referrals
A10: A-0009 | B10: Aya Healthcare | C10: Travel Nurse Agency | D10: Partner / Referral | E10: Travel nurse placements
A11: A-0010 | B11: AMN Healthcare | C11: Travel Nurse Agency | D11: Partner / Referral | E11: Travel nurse placements
A12: A-0011 | B12: Blueground | C12: Corporate Housing | D12: Partner / Referral | E12: Corporate placement partnership
... A19: A-0018 | B19: Internal Property Committee | C19: Internal | D19: Stakeholder | E19: Pricing and renovation decisions

Sheet Units
A1: unit_id | B1: property_id | C1: unit_label | D1: unit_type | E1: beds | F1: baths | G1: submarket | H1: current_status | I1: occupancy_status | J1: asking_rent_2024 | K1: asking_rent_2025 | L1: availability_date | M1: target_segment | N1: renovation_level
A2: U-0001 | B2: P-001 | C2: Studio-1 | D2: Studio | E2: 0 | F2: 1 | G2: Boston Core | H2: Resident In Place | I2: Occupied | J2: 2730 | K2: 3050 | M2: Graduate Students | N2: Partial Update
A3: U-0002 | B3: P-001 | C3: Studio-2 | D3: Studio | E3: 0 | F3: 1 | G3: Boston Core | H3: Resident In Place | I3: Occupied | J3: 2700 | K3: 2980 | M3: Graduate Students | N3: Partial Update
A4: U-0003 | B4: P-001 | C4: Studio-3 | D4: Studio | E4: 0 | F4: 1 | G4: Boston Core | H4: Resident In Place | I4: Occupied | J4: 2750 | K4: 3060 | M4: Graduate Students | N4: Partial Update
A5: U-0004 | B5: P-001 | C5: Studio-4 | D5: Studio | E5: 0 | F5: 1 | G5: Boston Core | H5: Resident In Place | I5: Occupied | J5: 2980 | K5: 3020 | M5: Graduate Students | N5: Classic
A6: U-0005 | B6: P-001 | C6: Studio-5 | D6: Studio | E6: 0 | F6: 1 | G6: Boston Core | H6: Resident In Place | I6: Occupied | J6: 2740 | K6: 3060 | M6: Graduate Students | N6: Partial Update
A7: U-0006 | B7: P-001 | C7: 1BD-6 | D7: 1BD | E7: 1 | F7: 1 | G7: Boston Core | H7: Turnover Scheduled | I7: Notice | J7: 3360 | K7: 3770 | L7: 45965 | M7: Graduate Students | N7: Partial Update
A8: U-0007 | B8: P-001 | C8: 1BD-7 | D8: 1BD | E8: 1 | F8: 1 | G8: Boston Core | H8: Turnover Scheduled | I8: Notice | J8: 3400 | K8: 3670 | L8: 45681 | M8: Graduate Students | N8: Classic
A9: U-0008 | B9: P-001 | C9: 1BD-8 | D9: 1BD | E9: 1 | F9: 1 | G9: Boston Core | H9: Resident In Place | I9: Occupied | J9: 3510 | K9: 3900 | M9: Graduate Students | N9: Partial Update
A10: U-0009 | B10: P-001 | C10: 2BD-9 | D10: 2BD | E10: 2 | F10: 1 | G10: Boston Core | H10: Resident In Place | I10: Occupied | J10: 4400 | K10: 4850 | M10: Graduate Students | N10: Classic
A11: U-0010 | B11: P-001 | C11: 2BD-10 | D11: 2BD | E11: 2 | F11: 1 | G11: Boston Core | H11: Resident In Place | I11: Occupied | J11: 4400 | K11: 4570 | M11: Graduate Students | N11: Needs Cosmetic Update
A12: U-0011 | B12: P-002 | C12: Studio-1 | D12: Studio | E12: 0 | F12: 1 | G12: Boston Core | H12: Resident In Place | I12: Occupied | J12: 2910 | K12: 2880 | M12: Graduate Students | N12: Partial Update
A13: U-0012 | B13: P-002 | C13: Studio-2 | D13: Studio | E13: 0 | F13: 1 | G13: Boston Core | H13: Resident In Place | I13: Occupied | J13: 2870 | K13: 3060 | M13: Graduate Students | N13: Classic
A14: U-0013 | B14: P-002 | C14: Studio-3 | D14: Studio | E14: 0 | F14: 1 | G14: Boston Core | H14: Resident In Place | I14: Occupied | J14: 2860 | K14: 2990 | M14: Graduate Students | N14: Partial Update
A15: U-0014 | B15: P-002 | C15: Studio-4 | D15: Studio | E15: 0 | F15: 1 | G15: Boston Core | H15: Resident In Place | I15: Occupied | J15: 2810 | K15: 2900 | M15: Graduate Students | N15: Partial Update
A16: U-0015 | B16: P-002 | C16: 1BD-5 | D16: 1BD | E16: 1 | F16: 1 | G16: Boston Core | H16: Resident In Place | I16: Occupied | J16: 3660 | K16: 3470 | M16: Graduate Students | N16: Classic
A17: U-0016 | B17: P-002 | C17: 1BD-6 | D17: 1BD | E17: 1 | F17: 1 | G17: Boston Core | H17: Resident In Place | I17: Occupied | J17: 3400 | K17: 3610 | M17: Graduate Students | N17: Partial Update
A18: U-0017 | B18: P-002 | C18: 1BD-7 | D18: 1BD | E18: 1 | F18: 1 | G18: Boston Core | H18: Resident In Place | I18: Occupied | J18: 3560 | K18: 3540 | M18: Graduate Students | N18: Classic
A19: U-0018 | B19: P-002 | C19: 1BD-8 | D19: 1BD | E19: 1 | F19: 1 | G19: Boston Core | H19: Resident In Place | I19: Occupied | J19: 3420 | K19: 3410 | M19: Graduate Students | N19: Classic
A20: U-0019 | B20: P-002 | C20: 2BD-9 | D20: 2BD | E20: 2 | F20: 1 | G20: Boston Core | H20: Resident In Place | I20: Occupied | J20: 4640 | K20: 4760 | M20: Graduate Students | N20: Needs Cosmetic Update
A21: U-0020 | B21: P-002 | C21: 2BD-10 | D21: 2BD | E21: 2 | F21: 1 | G21: Boston Core | H21: Turnover Scheduled | I21: Notice | J21: 4580 | K21: 4850 | L21: 45785 | M21: Graduate Students | N21: Partial Update
A22: U-0021 | B22: P-003 | C22: Studio-1 | D22: Studio | E22: 0 | F22: 1 | G22: Boston Core | H22: Resident In Place | I22: Occupied | J22: 2770 | K22: 2920 | M22: Graduate Students | N22: Classic
A23: U-0022 | B23: P-003 | C23: Studio-2 | D23: Studio | E23: 0 | F23: 1 | G23: Boston Core | H23: Resident In Place | I23: Occupied | J23: 2910 | K23: 2900 | M23: Graduate Students | N23: Classic
A24: U-0023 | B24: P-003 | C24: Studio-3 | D24: Studio | E24: 0 | F24: 1 | G24: Boston Core | H24: Resident In Place | I24: Occupied | J24: 2900 | K24: 3040 | M24: Graduate Students | N24: Classic
A25: U-0024 | B25: P-003 | C25: Studio-4 | D25: Studio | E25: 0 | F25: 1 | G25: Boston Core | H25: Resident In Place | I25: Occupied | J25: 2840 | K25: 2760 | M25: Graduate Students | N25: Classic
A26: U-0025 | B26: P-003 | C26: 1BD-5 | D26: 1BD | E26: 1 | F26: 1 | G26: Boston Core | H26: Resident In Place | I26: Occupied | J26: 3310 | K26: 3650 | M26: Graduate Students | N26: Partial Update
A27: U-0026 | B27: P-003 | C27: 1BD-6 | D27: 1BD | E27: 1 | F27: 1 | G27: Boston Core | H27: Resident In Place | I27: Occupied | J27: 3630 | K27: 3540 | M27: Graduate Students | N27: Partial Update
A28: U-0027 | B28: P-003 | C28: 1BD-7 | D28: 1BD | E28: 1 | F28: 1 | G28: Boston Core | H28: Resident In Place | I28: Occupied | J28: 3420 | K28: 3450 | M28: Graduate Students | N28: Partial Update
A29: U-0028 | B29: P-003 | C29: 2BD-8 | D29: 2BD | E29: 2 | F29: 1 | G29: Boston Core | H29: Resident In Place | I29: Occupied | J29: 4240 | K29: 4810 | M29: Graduate Students | N29: Partial Update
A30: U-0029 | B30: P-003 | C30: 2BD-9 | D30: 2BD | E30: 2 | F30: 1 | G30: Boston Core | H30: Resident In Place | I30: Occupied | J30: 4290 | K30: 4740 | M30: Graduate Students | N30: Needs Cosmetic Update
A31: U-0030 | B31: P-003 | C31: 2BD-10 | D31: 2BD | E31: 2 | F31: 1 | G31: Boston Core | H31: Resident In Place | I31: Occupied | J31: 4550 | K31: 5030 | M31: Graduate Students | N31: Needs Cosmetic Update
A32: U-0031 | B32: P-004 | C32: Studio-1 | D32: Studio | E32: 0 | F32: 1 | G32: Boston Core | H32: Resident In Place | I32: Occupied | J32: 2870 | K32: 2990 | M32: Graduate Students | N32: Classic
A33: U-0032 | B33: P-004 | C33: Studio-2 | D33: Studio | E33: 0 | F33: 1 | G33: Boston Core | H33: Resident In Place | I33: Occupied | J33: 2890 | K33: 3130 | M33: Graduate Students | N33: Partial Update
... A36: U-0035 | B36: P-005 | C36: Studio-1 | D36: Studio | E36: 0 | F36: 1 | G36: Boston Core | H36: Resident In Place | I36: Occupied | J36: 2950 | K36: 3200 | M36: Graduate Students | N36: Classic
A37: U-0036 | B37: P-005 | C37: Studio-2 | D37: Studio | E37: 0 | F37: 1 | G37: Boston Core | H37: Available | I37: Vacant | J37: 2740 | K37: 2710 | L37: 45752 | M37: Graduate Students | N37: Classic
A38: U-0037 | B38: P-005 | C38: 1BD-3 | D38: 1BD | E38: 1 | F38: 1 | G38: Boston Core | H38: Resident In Place | I38: Occupied | J38: 3390 | K38: 3500 | M38: Graduate Students | N38: Classic
A39: U-0038 | B39: P-005 | C39: 2BD-4 | D39: 2BD | E39: 2 | F39: 1 | G39: Boston Core | H39: Available | I39: Vacant | J39: 4580 | K39: 4700 | L39: 45995 | M39: Graduate Students | N39: Partial Update
A40: U-0039 | B40: P-006 | C40: 3BD-1 | D40: 3BD | E40: 3 | F40: 2 | G40: West Roxbury | H40: Resident In Place | I40: Occupied | J40: 3460 | K40: 3680 | M40: Working Professionals | N40: Partial Update
A41: U-0040 | B41: P-007 | C41: 2BD-2 | D41: 2BD | E41: 2 | F41: 1 | G41: West Roxbury | H41: Available | I41: Vacant | J41: 2990 | K41: 2890 | L41: 45985 | M41: Working Professionals | N41: Classic
A42: U-0041 | B42: P-008 | C42: 2BD-3 | D42: 2BD | E42: 2 | F42: 1 | G42: Dorchester | H42: Resident In Place | I42: Occupied | J42: 2650 | K42: 3160 | M42: Working Professionals | N42: Renovated
...

Sheet Campaigns
A1: campaign_id | B1: campaign_name | C1: campaign_type | D1: channel | E1: theme | F1: audience_segment | G1: start_date | H1: end_date | I1: budget | J1: target_kpi
A2: CP-001 | B2: Spring Leasing Kickoff | C2: Email Nurture | D2: Email | E2: Location + Convenience | F2: Tufts Medical / Dental / Law | G2: 45366 | H2: 45443 | I2: 1800 | J2: Open rate / Inquiry-to-tour
A3: CP-002 | B3: Summer Peak Leasing Push | C3: Email Nurture | D3: Email | E3: Availability + Move-in Timing | F3: Graduate Students | G3: 45444 | H3: 45535 | I3: 2400 | J3: Click-to-tour
A4: CP-003 | B4: September Waitlist Nurture | C4: Email Nurture | D4: Email | E4: Proximity + Waitlist | F4: Graduate Students | G4: 45536 | H4: 45580 | I4: 1200 | J4: Reply rate
A5: CP-004 | B5: Winter Price Refresh | C5: Email Nurture | D5: Email | E5: Price + Incentive | F5: Working Professionals | G5: 45627 | H5: 45703 | I5: 1600 | J5: Inquiry rate
A6: CP-005 | B6: Spring Leasing Kickoff 2025 | C6: Email Nurture | D6: Email | E6: Location + Convenience | F6: Tufts Medical / Dental / Law | G6: 45726 | H6: 45808 | I6: 2100 | J6: Open rate / Inquiry-to-tour
A7: CP-006 | B7: Summer Peak Leasing Push 2025 | C7: Email Nurture | D7: Email | E7: Availability + Move-in Timing | F7: Graduate Students | G7: 45809 | H7: 45900 | I7: 2800 | J7: Click-to-tour
A8: CP-007 | B8: Hospital Overflow Outreach | C8: Partner Outreach | D8: Email | E8: Furnished convenience + proximity | F8: Hospitals / Travel Nurses | G8: 45383 | H8: 46022 | I8: 3000 | J8: Qualified lead rate
A9: CP-008 | B9: Corporate Housing Outreach | C9: Partner Outreach | D9: Email | E9: Convenience + housing support | F9: Working Professionals | G9: 45383 | H9: 46022 | I9: 2500 | J9: Qualified lead rate
A10: CP-009 | B10: Zillow Premium Listing Refresh | C10: Paid Listing | D10: Zillow | E10: Location + photos | F10: Boston Core renters | G10: 45413 | H10: 46022 | I10: 7200 | J10: Lead volume
A11: CP-010 | B11: Apartments.com Featured Ads | C11: Paid Listing | D11: Apartments.com | E11: Location + price | F11: Boston Core renters | G11: 45413 | H11: 46022 | I11: 5400 | J11: Qualified lead rate
A12: CP-011 | B12: Realtor.com Visibility Boost | C12: Paid Listing | D12: Realtor.com | E12: Location + move-in | F12: Working Professionals | G12: 45444 | H12: 46022 | I12: 4200 | J12: Lead volume
A13: CP-012 | B13: MLS Open Listing Rotation | C13: Listing Distribution | D13: MLS | E13: Broker network visibility | F13: Agents / Co-broke | G13: 45292 | H13: 46022 | I13: 1800 | J13: Agent-sourced tours
... A19: CP-018 | B19: Building Update Status Note | C19: Email Nurture | D19: Email | E19: Transparency on updates | F19: 2BD prospects | G19: 45689 | H19: 45808 | I19: 600 | J19: Response rate

Sheet Leads
A1: lead_id | B1: contact_id | C1: account_id | D1: unit_id | E1: listing_id | F1: campaign_id | G1: inquiry_date | H1: lead_source | I1: lead_source_group | J1: qualify_status | K1: current_stage | L1: desired_move_in_date | M1: budget_band | N1: price_objection_flag | O1: location_objection_flag | P1: condition_objection_flag | Q1: closed_lost_reason | R1: lease_signed_date | S1: lease_value
A2: L-000001 | B2: C-00170 | C2: A-0001 | D2: U-0001 | E2: LS-00001 | F2: CP-005 | G2: 45901 | H2: School Referral | I2: Partner Referral | J2: Qualified | K2: Lease Signed | L2: 45936 | M2: $2,750-$3,250 | N2: No | O2: No | P2: No | R2: 45911 | S2: =IF(AND(K2="Lease Signed",R2<>""),INDEX(Units!$K:$K,MATCH(D2,Units!$A:$A,0))*12,0) -> 36600
A3: L-000002 | B3: C-00137 | C3: A-0001 | D3: U-0002 | E3: LS-00004 | F3: CP-016 | G3: 45941 | H3: Constant Contact Email | I3: Email Campaign | J3: Qualified | K3: Lease Signed | L3: 45974 | M3: $2,750-$3,250 | N3: No | O3: No | P3: No | R3: 45957 | S3: =IF(AND(K3="Lease Signed",R3<>""),INDEX(Units!$K:$K,MATCH(D3,Units!$A:$A,0))*12,0) -> 35760
A4: L-000003 | B4: C-00341 | C4: A-0001 | D4: U-0003 | E4: LS-00005 | F4: CP-006 | G4: 45778 | H4: Constant Contact Email | I4: Email Campaign | J4: Qualified | K4: Lease Signed | L4: 45843 | M4: $2,750-$3,250 | N4: No | O4: No | P4: No | R4: 45804 | S4: =IF(AND(K4="Lease Signed",R4<>""),INDEX(Units!$K:$K,MATCH(D4,Units!$A:$A,0))*12,0) -> 36720
A5: L-000004 | B5: C-00150 | C5: A-0002 | D5: U-0004 | E5: LS-00007 | F5: CP-009 | G5: 45917 | H5: Zillow | I5: Third-Party Listing | J5: Qualified | K5: Lease Signed | L5: 45983 | M5: $2,750-$3,250 | N5: No | O5: No | P5: No | R5: 45951 | S5: =IF(AND(K5="Lease Signed",R5<>""),INDEX(Units!$K:$K,MATCH(D5,Units!$A:$A,0))*12,0) -> 36240
A6: L-000005 | B6: C-00103 | C6: A-0016 | D6: U-0005 | E6: LS-00010 | F6: CP-017 | G6: 45797 | H6: Constant Contact Email | I6: Email Campaign | J6: Qualified | K6: Lease Signed | L6: 45819 | M6: $2,750-$3,250 | N6: No | O6: No | P6: No | R6: 45794 | S6: =IF(AND(K6="Lease Signed",R6<>""),INDEX(Units!$K:$K,MATCH(D6,Units!$A:$A,0))*12,0) -> 36720
A7: L-000006 | B7: C-00243 | C7: A-0003 | D7: U-0006 | E7: LS-00012 | F7: CP-012 | G7: 45332 | H7: MLS | I7: Agent Network | J7: Qualified | K7: Lease Signed | L7: 45675 | M7: $3,751-$4,500 | N7: No | O7: No | P7: No | R7: 45346 | S7: =IF(AND(K7="Lease Signed",R7<>""),INDEX(Units!$K:$K,MATCH(D7,Units!$A:$A,0))*12,0) -> 45240
A8: L-000007 | B8: C-00236 | C8: A-0003 | D8: U-0006 | E8: LS-00013 | F8: CP-010 | G8: 45929 | H8: Apartments.com | I8: Third-Party Listing | J8: Qualified | K8: Lease Signed | L8: 45975 | M8: $3,251-$3,750 | N8: No | O8: No | P8: No | R8: 45940 | S8: =IF(AND(K8="Lease Signed",R8<>""),INDEX(Units!$K:$K,MATCH(D8,Units!$A:$A,0))*12,0) -> 45240
A9: L-000008 | B9: C-00088 | C9: A-0016 | D9: U-0007 | E9: LS-00018 | F9: CP-006 | G9: 45321 | H9: Constant Contact Email | I9: Email Campaign | J9: Qualified | K9: Lease Signed | L9: 45753 | M9: $3,251-$3,750 | N9: No | O9: No | P9: Yes | R9: 45341 | S9: =IF(AND(K9="Lease Signed",R9<>""),INDEX(Units!$K:$K,MATCH(D9,Units!$A:$A,0))*12,0) -> 44040
A10: L-000009 | B10: C-00220 | C10: A-0001 | D10: U-0007 | E10: LS-00017 | F10: CP-010 | G10: 45813 | H10: Apartments.com | I10: Third-Party Listing | J10: Qualified | K10: Lease Signed | L10: 45874 | M10: $3,251-$3,750 | N10: No | O10: No | P10: No | R10: 45838 | S10: =IF(AND(K10="Lease Signed",R10<>""),INDEX(Units!$K:$K,MATCH(D10,Units!$A:$A,0))*12,0) -> 44040
A11: L-000010 | B11: C-00429 | C11: A-0001 | D11: U-0008 | E11: LS-00022 | F11: CP-005 | G11: 45873 | H11: School Referral | I11: Partner Referral | J11: Qualified | K11: Lease Signed | L11: 45937 | M11: $2,750-$3,250 | N11: No | O11: No | P11: No | R11: 45898 | S11: =IF(AND(K11="Lease Signed",R11<>""),INDEX(Units!$K:$K,MATCH(D11,Units!$A:$A,0))*12,0) -> 46800
A12: L-000011 | B12: C-00166 | C12: A-0002 | D12: U-0009 | E12: LS-00023 | F12: CP-010 | G12: 45958 | H12: Apartments.com | I12: Third-Party Listing | J12: Qualified | K12: Lease Signed | L12: 45981 | M12: $4,501+ | N12: No | O12: No | P12: No | R12: 45941 | S12: =IF(AND(K12="Lease Signed",R12<>""),INDEX(Units!$K:$K,MATCH(D12,Units!$A:$A,0))*12,0) -> 58200
A13: L-000012 | B13: C-00166 | C13: A-0002 | D13: U-0010 | E13: LS-00026 | F13: CP-010 | G13: 45529 | H13: Apartments.com | I13: Third-Party Listing | J13: Qualified | K13: Lease Signed | L13: 45961 | M13: $4,501+ | N13: No | O13: No | P13: No | R13: 45504 | S13: =IF(AND(K13="Lease Signed",R13<>""),INDEX(Units!$K:$K,MATCH(D13,Units!$A:$A,0))*12,0) -> 54840
... A18: L-000017 | B18: C-00301 | C18: A-0002 | D18: U-0013 | E18: LS-00031 | F18: CP-010 | G18: 45845 | H18: Apartments.com | I18: Third-Party Listing | J18: Qualified | K18: Lease Signed | L18: 45880 | M18: $2,750-$3,250 | N18: No | O18: No | P18: No | R18: 45851 | S18: =IF(AND(K18="Lease Signed",R18<>""),INDEX(Units!$K:$K,MATCH(D18,Units!$A:$A,0))*12,0) -> 35880
A19: L-000018 | B19: C-00384 | C19: A-0002 | D19: U-0014 | E19: LS-00034 | G19: 45846 | H19: Website Inquiry | I19: Direct / Organic | J19: Qualified | K19: Lease Signed | L19: 45903 | M19: $2,750-$3,250 | N19: No | O19: No | P19: No | R19: 45868 | S19: =IF(AND(K19="Lease Signed",R19<>""),INDEX(Units!$K:$K,MATCH(D19,Units!$A:$A,0))*12,0) -> 34800
A20: L-000019 | B20: C-00389 | C20: A-0002 | D20: U-0015 | E20: LS-00036 | F20: CP-009 | G20: 45447 | H20: Zillow | I20: Third-Party Listing | J20: Qualified | K20: Lease Signed | L20: 45823 | M20: $3,251-$3,750 | N20: No | O20: No | P20: No | R20: 45440 | S20: =IF(AND(K20="Lease Signed",R20<>""),INDEX(Units!$K:$K,MATCH(D20,Units!$A:$A,0))*12,0) -> 41640
A21: L-000020 | B21: C-00161 | C21: A-0015 | D21: U-0015 | E21: LS-00036 | F21: CP-003 | G21: 45753 | H21: Constant Contact Email | I21: Email Campaign | J21: Qualified | K21: Lease Signed | L21: 45791 | M21: $3,251-$3,750 | N21: No | O21: No | P21: No | R21: 45754 | S21: =IF(AND(K21="Lease Signed",R21<>""),INDEX(Units!$K:$K,MATCH(D21,Units!$A:$A,0))*12,0) -> 41640
A22: L-000021 | B22: C-00284 | C22: A-0001 | D22: U-0016 | E22: LS-00037 | F22: CP-010 | G22: 45746 | H22: Apartments.com | I22: Third-Party Listing | J22: Qualified | K22: Lease Signed | L22: 45813 | M22: $3,251-$3,750 | N22: No | O22: No | P22: No | R22: 45794 | S22: =IF(AND(K22="Lease Signed",R22<>""),INDEX(Units!$K:$K,MATCH(D22,Units!$A:$A,0))*12,0) -> 43320
A23: L-000022 | B23: C-00447 | C23: A-0001 | D23: U-0017 | E23: LS-00039 | F23: CP-004 | G23: 45269 | H23: Constant Contact Email | I23: Email Campaign | J23: Qualified | K23: Lease Signed | L23: 45643 | M23: $3,251-$3,750 | N23: No | O23: No | P23: No | R23: 45284 | S23: =IF(AND(K23="Lease Signed",R23<>""),INDEX(Units!$K:$K,MATCH(D23,Units!$A:$A,0))*12,0) -> 42480
A24: L-000023 | B24: C-00034 | C24: A-0003 | D24: U-0017 | E24: LS-00039 | F24: CP-005 | G24: 45745 | H24: School Referral | I24: Partner Referral | J24: Qualified | K24: Lease Signed | L24: 45812 | M24: $3,251-$3,750 | N24: No | O24: No | P24: No | R24: 45797 | S24: =IF(AND(K24="Lease Signed",R24<>""),INDEX(Units!$K:$K,MATCH(D24,Units!$A:$A,0))*12,0) -> 42480
A25: L-000024 | B25: C-00131 | C25: A-0015 | D25: U-0018 | E25: LS-00042 | F25: CP-014 | G25: 45820 | H25: Constant Contact Email | I25: Email Campaign | J25: Qualified | K25: Lease Signed | L25: 45859 | M25: $2,750-$3,250 | N25: No | O25: No | P25: No | R25: 45844 | S25: =IF(AND(K25="Lease Signed",R25<>""),INDEX(Units!$K:$K,MATCH(D25,Units!$A:$A,0))*12,0) -> 40920
A26: L-000025 | B26: C-00271 | C26: A-0015 | D26: U-0019 | E26: LS-00044 | F26: CP-005 | G26: 45852 | H26: School Referral | I26: Partner Referral | J26: Qualified | K26: Lease Signed | L26: 45887 | M26: $4,501+ | N26: No | O26: No | P26: No | R26: 45846 | S26: =IF(AND(K26="Lease Signed",R26<>""),INDEX(Units!$K:$K,MATCH(D26,Units!$A:$A,0))*12,0) -> 57120
A27: L-000026 | B27: C-00374 | C27: A-0003 | D27: U-0020 | E27: LS-00047 | F27: CP-016 | G27: 45353 | H27: Constant Contact Email | I27: Email Campaign | J27: Qualified | K27: Lease Signed | L27: 45755 | M27: $4,501+ | N27: No | O27: No | P27: No | R27: 45321 | S27: =IF(AND(K27="Lease Signed",R27<>""),INDEX(Units!$K:$K,MATCH(D27,Units!$A:$A,0))*12,0) -> 58200
A28: L-000027 | B28: C-00050 | C28: A-0002 | D28: U-0020 | E28: LS-00047 | G28: 45820 | H28: Website Inquiry | I28: Direct / Organic | J28: Qualified | K28: Lease Signed | L28: 45846 | M28: $3,751-$4,500 | N28: Yes | O28: No | P28: No | R28: 45807 | S28: =IF(AND(K28="Lease Signed",R28<>""),INDEX(Units!$K:$K,MATCH(D28,Units!$A:$A,0))*12,0) -> 58200
A29: L-000028 | B29: C-00301 | C29: A-0002 | D29: U-0021 | E29: LS-00050 | F29: CP-010 | G29: 45927 | H29: Apartments.com | I29: Third-Party Listing | J29: Qualified | K29: Lease Signed | L29: 45967 | M29: <$2,750 | N29: No | O29: No | P29: No | R29: 45923 | S29: =IF(AND(K29="Lease Signed",R29<>""),INDEX(Units!$K:$K,MATCH(D29,Units!$A:$A,0))*12,0) -> 35040
A30: L-000029 | B30: C-00074 | C30: A-0002 | D30: U-0022 | E30: LS-00052 | F30: CP-001 | G30: 45753 | H30: School Referral | I30: Partner Referral | J30: Qualified | K30: Lease Signed | L30: 45790 | M30: $2,750-$3,250 | N30: No | O30: No | P30: No | R30: 45768 | S30: =IF(AND(K30="Lease Signed",R30<>""),INDEX(Units!$K:$K,MATCH(D30,Units!$A:$A,0))*12,0) -> 34800
A31: L-000030 | B31: C-00353 | C31: A-0003 | D31: U-0023 | E31: LS-00055 | F31: CP-009 | G31: 45346 | H31: Zillow | I31: Third-Party Listing | J31: Qualified | K31: Lease Signed | L31: 45717 | M31: $2,750-$3,250 | N31: No | O31: No | P31: No | R31: 45347 | S31: =IF(AND(K31="Lease Signed",R31<>""),INDEX(Units!$K:$K,MATCH(D31,Units!$A:$A,0))*12,0) -> 36480
A32: L-000031 | B32: C-00199 | C32: A-0009 | D32: U-0023 | E32: LS-00054 | F32: CP-001 | G32: 45778 | H32: School Referral | I32: Partner Referral | J32: Qualified | K32: Lease Signed | L32: 45842 | M32: $2,750-$3,250 | N32: No | O32: No | P32: No | R32: 45801 | S32: =IF(AND(K32="Lease Signed",R32<>""),INDEX(Units!$K:$K,MATCH(D32,Units!$A:$A,0))*12,0) -> 36480
A33: L-000032 | B33: C-00016 | C33: A-0001 | D33: U-0024 | E33: LS-00056 | F33: CP-018 | G33: 45264 | H33: Constant Contact Email | I33: Email Campaign | J33: Qualified | K33: Lease Signed | L33: 45656 | M33: $2,750-$3,250 | N33: No | O33: No | P33: No | R33: 45271 | S33: =IF(AND(K33="Lease Signed",R33<>""),INDEX(Units!$K:$K,MATCH(D33,Units!$A:$A,0))*12,0) -> 33120
A34: L-000033 | B34: C-00275 | C34: A-0001 | D34: U-0024 | E34: LS-00056 | F34: CP-004 | G34: 45777 | H34: Constant Contact Email | I34: Email Campaign | J34: Qualified | K34: Lease Signed | L34: 45823 | M34: $2,750-$3,250 | N34: No | O34: No | P34: No | R34: 45807 | S34: =IF(AND(K34="Lease Signed",R34<>""),INDEX(Units!$K:$K,MATCH(D34,Units!$A:$A,0))*12,0) -> 33120
A35: L-000034 | B35: C-00132 | C35: A-0002 | D35: U-0025 | E35: LS-00058 | F35: CP-012 | G35: 46013 | H35: MLS | I35: Agent Network | J35: Qualified | K35: Lease Signed | L35: 46043 | M35: $3,251-$3,750 | N35: No | O35: No | P35: No | R35: 46023 | S35: =IF(AND(K35="Lease Signed",R35<>""),INDEX(Units!$K:$K,MATCH(D35,Units!$A:$A,0))*12,0) -> 43800
A36: L-000035 | B36: C-00068 | C36: A-0003 | D36: U-0026 | E36: LS-00061 | F36: CP-009 | G36: 45445 | H36: Zillow | I36: Third-Party Listing | J36: Qualified | K36: Lease Signed | L36: 45875 | M36: $3,251-$3,750 | N36: No | O36: No | P36: No | R36: 45464 | S36: =IF(AND(K36="Lease Signed",R36<>""),INDEX(Units!$K:$K,MATCH(D36,Units!$A:$A,0))*12,0) -> 42480
A37: L-000036 | B37: C-00403 | C37: A-0016 | D37: U-0026 | E37: LS-00061 | G37: 46020 | H37: Website Inquiry | I37: Direct / Organic | J37: Qualified | K37: Lease Signed | L37: 46076 | M37: $3,251-$3,750 | N37: No | O37: No | P37: No | R37: 46060 | S37: =IF(AND(K37="Lease Signed",R37<>""),INDEX(Units!$K:$K,MATCH(D37,Units!$A:$A,0))*12,0) -> 42480
A38: L-000037 | B38: C-00082 | C38: A-0002 | D38: U-0027 | E38: LS-00063 | F38: CP-010 | G38: 45714 | H38: Apartments.com | I38: Third-Party Listing | J38: Qualified | K38: Lease Signed | L38: 45779 | M38: $2,750-$3,250 | N38: No | O38: No | P38: No | R38: 45741 | S38: =IF(AND(K38="Lease Signed",R38<>""),INDEX(Units!$K:$K,MATCH(D38,Units!$A:$A,0))*12,0) -> 41400
A39: L-000038 | B39: C-00066 | C39: A-0003 | D39: U-0028 | E39: LS-00064 | F39: CP-009 | G39: 45922 | H39: Zillow | I39: Third-Party Listing | J39: Qualified | K39: Lease Signed | L39: 45974 | M39: $4,501+ | N39: No | O39: No | P39: No | R39: 45946 | S39: =IF(AND(K39="Lease Signed",R39<>""),INDEX(Units!$K:$K,MATCH(D39,Units!$A:$A,0))*12,0) -> 57720
A40: L-000039 | B40: C-00047 | C40: A-0001 | D40: U-0029 | E40: LS-00066 | F40: CP-001 | G40: 45854 | H40: School Referral | I40: Partner Referral | J40: Qualified | K40: Lease Signed | L40: 45903 | M40: $4,501+ | N40: Yes | O40: No | P40: No | R40: 45886 | S40: =IF(AND(K40="Lease Signed",R40<>""),INDEX(Units!$K:$K,MATCH(D40,Units!$A:$A,0))*12,0) -> 56880
A41: L-000040 | B41: C-00021 | C41: A-0001 | D41: U-0030 | E41: LS-00069 | F41: CP-009 | G41: 45496 | H41: Zillow | I41: Third-Party Listing | J41: Qualified | K41: Lease Signed | L41: 45928 | M41: $3,751-$4,500 | N41: No | O41: No | P41: Yes | R41: 45498 | S41: =IF(AND(K41="Lease Signed",R41<>""),INDEX(Units!$K:$K,MATCH(D41,Units!$A:$A,0))*12,0) -> 60360
A42: L-000041 | B42: C-00021 | C42: A-0003 | D42: U-0030 | E42: LS-00069 | F42: CP-010 | G42: 45904 | H42: Apartments.com | I42: Third-Party Listing | J42: Qualified | K42: Lease Signed | L42: 45968 | M42: $4,501+ | N42: No | O42: No | P42: No | R42: 45947 | S42: =IF(AND(K42="Lease Signed",R42<>""),INDEX(Units!$K:$K,MATCH(D42,Units!$A:$A,0))*12,0) -> 60360
A43: L-000042 | B43: C-00151 | C43: A-0001 | D43: U-0031 | E43: LS-00070 | F43: CP-002 | G43: 45306 | H43: Constant Contact Email | I43: Email Campaign | J43: Qualified | K43: Lease Signed | L43: 45731 | M43: $2,750-$3,250 | N43: No | O43: No | P43: Yes | R43: 45307 | S43: =IF(AND(K43="Lease Signed",R43<>""),INDEX(Units!$K:$K,MATCH(D43,Units!$A:$A,0))*12,0) -> 35880
A44: L-000043 | B44: C-00219 | C44: A-0002 | D44: U-0031 | E44: LS-00071 | F44: CP-012 | G44: 45839 | H44: MLS | I44: Agent Network | J44: Qualified | K44: Lease Signed | L44: 45882 | M44: $2,750-$3,250 | N44: No | O44: No | P44: No | R44: 45863 | S44: =IF(AND(K44="Lease Signed",R44<>""),INDEX(Units!$K:$K,MATCH(D44,Units!$A:$A,0))*12,0) -> 35880
...

Sheet Activities
A1: activity_id | B1: lead_id | C1: campaign_id | D1: activity_date | E1: activity_type | F1: activity_owner | G1: result | H1: next_followup_date | I1: notes
A2: T-0000001 | B2: L-000001 | C2: CP-005 | D2: 45901 | E2: Marketing Touch | F2: Marketing Coordinator | G2: Viewed / clicked | H2: 45901 | I2: Attributed to School Referral
A3: T-0000002 | B3: L-000001 | D3: 45901 | E3: Inbound Inquiry | F3: Ariana Seymourian | G3: School Referral | H3: 45902 | I3: Lead entered CRM
A4: T-0000003 | B4: L-000001 | D4: 45902 | E4: Phone | F4: Ariana Seymourian | G4: Initial outreach | H4: 45904 | I4: First contact attempt
A5: T-0000004 | B5: L-000001 | D5: 45903 | E5: Follow-up | F5: Ariana Seymourian | G5: Left voicemail | H5: 45905
A6: T-0000005 | B6: L-000001 | D6: 45906 | E6: Follow-up | F6: Ariana Seymourian | G6: Reached | H6: 45911
A7: T-0000006 | B7: L-000001 | D7: 45906 | E7: Tour | F7: Ariana Seymourian | G7: Completed | H7: 45907 | I7: In-person or virtual tour
A8: T-0000007 | B8: L-000001 | D8: 45911 | E8: Application | F8: Ariana Seymourian | G8: Submitted | H8: 45913 | I8: Documents collected
A9: T-0000008 | B9: L-000001 | D9: 45911 | E9: Lease | F9: Ariana Seymourian | G9: Signed | I9: Lease executed
A10: T-0000009 | B10: L-000002 | C10: CP-016 | D10: 45937 | E10: Marketing Touch | F10: Marketing Coordinator | G10: Viewed / clicked | H10: 45941 | I10: Attributed to Constant Contact Email
A11: T-0000010 | B11: L-000002 | C11: CP-016 | D11: 45941 | E11: Inbound Inquiry | F11: Ariana Seymourian | G11: Constant Contact Email | H11: 45942 | I11: Lead entered CRM
A12: T-0000011 | B12: L-000002 | D12: 45942 | E12: Phone | F12: Ariana Seymourian | G12: Initial outreach | H12: 45944 | I12: First contact attempt
A13: T-0000012 | B13: L-000002 | D13: 45944 | E13: Follow-up | F13: Ariana Seymourian | G13: Sent pricing | H13: 45947
A14: T-0000013 | B14: L-000002 | D14: 45946 | E14: Follow-up | F14: Ariana Seymourian | G14: Discussed objections | H14: 45951
A15: T-0000014 | B15: L-000002 | D15: 45954 | E15: Tour | F15: Ariana Seymourian | G15: Completed | H15: 45955 | I15: In-person or virtual tour
A16: T-0000015 | B16: L-000002 | D16: 45952 | E16: Application | F16: Ariana Seymourian | G16: Submitted | H16: 45954 | I16: Documents collected
A17: T-0000016 | B17: L-000002 | D17: 45957 | E17: Lease | F17: Ariana Seymourian | G17: Signed | I17: Lease executed
A18: T-0000017 | B18: L-000003 | C18: CP-006 | D18: 45778 | E18: Marketing Touch | F18: Marketing Coordinator | G18: Viewed / clicked | H18: 45778 | I18: Attributed to Constant Contact Email
A19: T-0000018 | B19: L-000003 | C19: CP-006 | D19: 45778 | E19: Inbound Inquiry | F19: Ariana Seymourian | G19: Constant Contact Email | H19: 45779 | I19: Lead entered CRM
A20: T-0000019 | B20: L-000003 | D20: 45778 | E20: Text | F20: Ariana Seymourian | G20: Initial outreach | H20: 45780 | I20: First contact attempt
A21: T-0000020 | B21: L-000003 | D21: 45779 | E21: Follow-up | F21: Ariana Seymourian | G21: Sent availability | H21: 45783
A22: T-0000021 | B22: L-000003 | D22: 45781 | E22: Follow-up | F22: Ariana Seymourian | G22: Reached | H22: 45784
A23: T-0000022 | B23: L-000003 | D23: 45785 | E23: Follow-up | F23: Ariana Seymourian | G23: Discussed objections | H23: 45790
A24: T-0000023 | B24: L-000003 | D24: 45789 | E24: Follow-up | F24: Ariana Seymourian | G24: Sent pricing | H24: 45791
A25: T-0000024 | B25: L-000003 | D25: 45785 | E25: Tour | F25: Ariana Seymourian | G25: Completed | H25: 45786 | I25: In-person or virtual tour
A26: T-0000025 | B26: L-000003 | D26: 45790 | E26: Application | F26: Ariana Seymourian | G26: Submitted | H26: 45792 | I26: Documents collected
A27: T-0000026 | B27: L-000003 | D27: 45804 | E27: Lease | F27: Ariana Seymourian | G27: Signed | I27: Lease executed
A28: T-0000027 | B28: L-000004 | C28: CP-009 | D28: 45916 | E28: Marketing Touch | F28: Marketing Coordinator | G28: Viewed / clicked | H28: 45917 | I28: Attributed to Zillow
A29: T-0000028 | B29: L-000004 | D29: 45917 | E29: Inbound Inquiry | F29: Leasing Associate | G29: Zillow | H29: 45918 | I29: Lead entered CRM
A30: T-0000029 | B30: L-000004 | D30: 45918 | E30: Text | F30: Leasing Associate | G30: Initial outreach | H30: 45920 | I30: First contact attempt
A31: T-0000030 | B31: L-000004 | D31: 45920 | E31: Follow-up | F31: Leasing Associate | G31: Discussed objections | H31: 45923
A32: T-0000031 | B32: L-000004 | D32: 45921 | E32: Follow-up | F32: Leasing Associate | G32: Reached | H32: 45924
A33: T-0000032 | B33: L-000004 | D33: 45928 | E33: Tour | F33: Leasing Associate | G33: Completed | H33: 45929 | I33: In-person or virtual tour
A34: T-0000033 | B34: L-000004 | D34: 45923 | E34: Application | F34: Leasing Associate | G34: Submitted | H34: 45925 | I34: Documents collected
A35: T-0000034 | B35: L-000004 | D35: 45951 | E35: Lease | F35: Leasing Associate | G35: Signed | I35: Lease executed
A36: T-0000035 | B36: L-000005 | C36: CP-017 | D36: 45794 | E36: Marketing Touch | F36: Marketing Coordinator | G36: Viewed / clicked | H36: 45797 | I36: Attributed to Constant Contact Email
A37: T-0000036 | B37: L-000005 | C37: CP-017 | D37: 45797 | E37: Inbound Inquiry | F37: Leasing Associate | G37: Constant Contact Email | H37: 45798 | I37: Lead entered CRM
A38: T-0000037 | B38: L-000005 | D38: 45799 | E38: Text | F38: Leasing Associate | G38: Initial outreach | H38: 45801 | I38: First contact attempt
A39: T-0000038 | B39: L-000005 | D39: 45801 | E39: Follow-up | F39: Leasing Associate | G39: No response | H39: 45805
A40: T-0000039 | B40: L-000005 | D40: 45803 | E40: Follow-up | F40: Leasing Associate | G40: Reached | H40: 45808
...

Sheet Properties
A1: property_id | B1: property_name | C1: address_or_area | D1: submarket | E1: property_type | F1: building_type | G1: total_units | H1: primary_unit_mix | I1: target_segment | J1: notes
A2: P-001 | B2: Chinatown Building A | C2: Chinatown / Downtown Boston | D2: Boston Core | E2: Apartment Building | F2: Walk-up | G2: 10 | H2: Studio / 1BR / 2BR | I2: Graduate Students | J2: High-demand location near Tufts and NESL
A3: P-002 | B3: Chinatown Building B | C3: Chinatown / Downtown Boston | D3: Boston Core | E3: Apartment Building | F3: Walk-up | G3: 10 | H3: Studio / 1BR / 2BR | I3: Graduate Students | J3: Primary student-driven demand
A4: P-003 | B4: Chinatown Building C | C4: Chinatown / Downtown Boston | D4: Boston Core | E4: Apartment Building | F4: Walk-up | G4: 10 | H4: Studio / 1BR / 2BR | I4: Graduate Students | J4: Older asset; price sensitivity on 2BRs
A5: P-004 | B5: Chinatown Building D | C5: Chinatown / Downtown Boston | D5: Boston Core | E5: Apartment Building | F5: Walk-up | G5: 4 | H5: Studio / 1BR | I5: Graduate Students | J5: Small walk-up asset
A6: P-005 | B6: Chinatown Building E | C6: Chinatown / Downtown Boston | D6: Boston Core | E6: Apartment Building | F6: Walk-up | G6: 4 | H6: Studio / 1BR | I6: Graduate Students | J6: Small walk-up asset
A7: P-006 | B7: West Roxbury House A | C7: West Roxbury | D7: West Roxbury | E7: Single Family Home | F7: Non-walk-up | G7: 1 | H7: 3BD / 2BA | I7: Working Professionals | J7: Larger-format family rental
A8: P-007 | B8: West Roxbury Home B | C8: West Roxbury | D8: West Roxbury | E8: Multi-Family Home | F8: Non-walk-up | G8: 1 | H8: 2BD / 1BA | I8: Working Professionals | J8: Neighborhood rental
A9: P-008 | B9: Dorchester Home A | C9: Dorchester | D9: Dorchester | E9: Multi-Family Home | F9: Non-walk-up | G9: 1 | H9: 2BD / 1BA | I9: Working Professionals | J9: Neighborhood rental
A10: P-009 | B10: Dorchester Home B | C10: Dorchester | D10: Dorchester | E10: Multi-Family Home | F10: Non-walk-up | G10: 1 | H10: 2BD / 1BA | I10: Working Professionals | J10: Neighborhood rental
A11: P-010 | B11: Dorchester Mixed-Use | C11: Dorchester | D11: Dorchester | E11: Mixed Residential / Commercial | F11: Non-walk-up | G11: 20 | H11: 2BD / 1BA | I11: Working Professionals | J11: Commercial building with residential units
A12: P-011 | B12: Foxboro Condo | C12: Foxboro | D12: Foxboro | E12: Condo / Apartment | F12: Non-walk-up | G12: 1 | H12: 2BD / 2BA | I12: Working Professionals | J12: Suburban option
A13: P-012 | B13: South End Condo | C13: South End Boston | D13: South End | E13: Condo / Apartment | F13: Non-walk-up | G13: 1 | H13: 3BD / 2BA | I13: Working Professionals | J13: Higher-end urban option

Sheet Listings
A1: listing_id | B1: unit_id | C1: platform | D1: listing_start_date | E1: listing_end_date | F1: listing_status | G1: featured_flag | H1: asking_rent | I1: days_on_market | J1: listing_notes
A2: LS-00001 | B2: U-0001 | C2: Zillow | D2: 45873 | E2: 45922 | F2: Closed | G2: No | H2: 2960 | I2: =IF(E2="",TODAY()-D2,E2-D2) -> 49 | J2: Primary student-focused listing
A3: LS-00002 | B3: U-0001 | C3: Apartments.com | D3: 45385 | E3: 45424 | F3: Closed | G3: Yes | H3: 2720 | I3: =IF(E3="",TODAY()-D3,E3-D3) -> 39 | J3: Primary student-focused listing
A4: LS-00003 | B4: U-0002 | C4: MLS | D4: 45659 | E4: 45720 | F4: Closed | G4: No | H4: 2980 | I4: =IF(E4="",TODAY()-D4,E4-D4) -> 61 | J4: Primary student-focused listing
A5: LS-00004 | B5: U-0002 | C5: MLS | D5: 45311 | E5: 45328 | F5: Closed | G5: No | H5: 2700 | I5: =IF(E5="",TODAY()-D5,E5-D5) -> 17 | J5: Primary student-focused listing
A6: LS-00005 | B6: U-0003 | C6: Apartments.com | D6: 45430 | E6: 45443 | F6: Closed | G6: Yes | H6: 2680 | I6: =IF(E6="",TODAY()-D6,E6-D6) -> 13 | J6: Primary student-focused listing
A7: LS-00006 | B7: U-0003 | C7: Apartments.com | D7: 45464 | E7: 45493 | F7: Closed | G7: Yes | H7: 2770 | I7: =IF(E7="",TODAY()-D7,E7-D7) -> 29 | J7: Primary student-focused listing
A8: LS-00007 | B8: U-0004 | C8: MLS | D8: 45419 | E8: 45471 | F8: Closed | G8: No | H8: 2980 | I8: =IF(E8="",TODAY()-D8,E8-D8) -> 52 | J8: Primary student-focused listing
A9: LS-00008 | B9: U-0004 | C9: Zillow | D9: 45962 | E9: 46000 | F9: Closed | G9: Yes | H9: 2980 | I9: =IF(E9="",TODAY()-D9,E9-D9) -> 38 | J9: Primary student-focused listing
A10: LS-00009 | B10: U-0005 | C10: MLS | D10: 45916 | E10: 45972 | F10: Closed | G10: No | H10: 3060 | I10: =IF(E10="",TODAY()-D10,E10-D10) -> 56 | J10: Primary student-focused listing
A11: LS-00010 | B11: U-0005 | C11: Zillow | D11: 45841 | E11: 45893 | F11: Closed | G11: No | H11: 3110 | I11: =IF(E11="",TODAY()-D11,E11-D11) -> 52 | J11: Primary student-focused listing
A12: LS-00011 | B12: U-0006 | C12: Zillow | D12: 45940 | F12: Active | G12: Yes | H12: 3890 | I12: =IF(E12="",TODAY()-D12,E12-D12) -> 193 | J12: Primary student-focused listing
A13: LS-00012 | B13: U-0006 | C13: Apartments.com | D13: 45942 | F13: Active | G13: Yes | H13: 3640 | I13: =IF(E13="",TODAY()-D13,E13-D13) -> 191 | J13: Primary student-focused listing
A14: LS-00013 | B14: U-0006 | C14: MLS | D14: 45944 | F14: Active | G14: No | H14: 3770 | I14: =IF(E14="",TODAY()-D14,E14-D14) -> 189 | J14: Primary student-focused listing
A15: LS-00014 | B15: U-0006 | C15: Zillow | D15: 45672 | E15: 45724 | F15: Closed | G15: No | H15: 3880 | I15: =IF(E15="",TODAY()-D15,E15-D15) -> 52 | J15: Primary student-focused listing
A16: LS-00015 | B16: U-0006 | C16: Apartments.com | D16: 45732 | E16: 45758 | F16: Closed | G16: Yes | H16: 3810 | I16: =IF(E16="",TODAY()-D16,E16-D16) -> 26 | J16: Primary student-focused listing
A17: LS-00016 | B17: U-0007 | C17: Zillow | D17: 45658 | F17: Active | G17: Yes | H17: 3710 | I17: =IF(E17="",TODAY()-D17,E17-D17) -> 475 | J17: Primary student-focused listing
A18: LS-00017 | B18: U-0007 | C18: Apartments.com | D18: 45662 | F18: Active | G18: Yes | H18: 3670 | I18: =IF(E18="",TODAY()-D18,E18-D18) -> 471 | J18: Primary student-focused listing
A19: LS-00018 | B19: U-0007 | C19: MLS | D19: 45659 | F19: Active | G19: No | H19: 3670 | I19: =IF(E19="",TODAY()-D19,E19-D19) -> 474 | J19: Primary student-focused listing
A20: LS-00019 | B20: U-0007 | C20: Apartments.com | D20: 45616 | E20: 45650 | F20: Closed | G20: Yes | H20: 3400 | I20: =IF(E20="",TODAY()-D20,E20-D20) -> 34 | J20: Primary student-focused listing
A21: LS-00020 | B21: U-0007 | C21: MLS | D21: 45420 | E21: 45458 | F21: Closed | G21: No | H21: 3400 | I21: =IF(E21="",TODAY()-D21,E21-D21) -> 38 | J21: Primary student-focused listing
A22: LS-00021 | B22: U-0008 | C22: MLS | D22: 45456 | E22: 45497 | F22: Closed | G22: No | H22: 3510 | I22: =IF(E22="",TODAY()-D22,E22-D22) -> 41 | J22: Primary student-focused listing
A23: LS-00022 | B23: U-0008 | C23: Apartments.com | D23: 45586 | E23: 45611 | F23: Closed | G23: No | H23: 3480 | I23: =IF(E23="",TODAY()-D23,E23-D23) -> 25 | J23: Primary student-focused listing
A24: LS-00023 | B24: U-0009 | C24: MLS | D24: 45934 | E24: 45953 | F24: Closed | G24: No | H24: 4850 | I24: =IF(E24="",TODAY()-D24,E24-D24) -> 19 | J24: 2BD received heavier promotion due to slower velocity
A25: LS-00024 | B25: U-0009 | C25: Apartments.com | D25: 45387 | E25: 45442 | F25: Closed | G25: Yes | H25: 4390 | I25: =IF(E25="",TODAY()-D25,E25-D25) -> 55 | J25: 2BD received heavier promotion due to slower velocity
A26: LS-00025 | B26: U-0010 | C26: Apartments.com | D26: 45724 | E26: 45765 | F26: Closed | G26: No | H26: 4510 | I26: =IF(E26="",TODAY()-D26,E26-D26) -> 41 | J26: 2BD received heavier promotion due to slower velocity
A27: LS-00026 | B27: U-0010 | C27: MLS | D27: 45901 | E27: 45916 | F27: Closed | G27: No | H27: 4570 | I27: =IF(E27="",TODAY()-D27,E27-D27) -> 15 | J27: 2BD received heavier promotion due to slower velocity
A28: LS-00027 | B28: U-0011 | C28: Zillow | D28: 45414 | E28: 45461 | F28: Closed | G28: Yes | H28: 2850 | I28: =IF(E28="",TODAY()-D28,E28-D28) -> 47 | J28: Primary student-focused listing
A29: LS-00028 | B29: U-0011 | C29: Zillow | D29: 45753 | E29: 45782 | F29: Closed | G29: Yes | H29: 2920 | I29: =IF(E29="",TODAY()-D29,E29-D29) -> 29 | J29: Primary student-focused listing
A30: LS-00029 | B30: U-0012 | C30: Apartments.com | D30: 45397 | E30: 45414 | F30: Closed | G30: No | H30: 2900 | I30: =IF(E30="",TODAY()-D30,E30-D30) -> 17 | J30: Primary student-focused listing
A31: LS-00030 | B31: U-0012 | C31: MLS | D31: 45855 | E31: 45915 | F31: Closed | G31: No | H31: 3060 | I31: =IF(E31="",TODAY()-D31,E31-D31) -> 60 | J31: Primary student-focused listing
... A45: LS-00044 | B45: U-0019 | C45: MLS | D45: 45879 | E45: 45930 | F45: Closed | G45: No | H45: 4760 | I45: =IF(E45="",TODAY()-D45,E45-D45) -> 51 | J45: 2BD received heavier promotion due to slower velocity
A46: LS-00045 | B46: U-0020 | C46: Zillow | D46: 45764 | F46: Active | G46: Yes | H46: 4870 | I46: =IF(E46="",TODAY()-D46,E46-D46) -> 369 | J46: 2BD received heavier promotion due to slower velocity
A47: LS-00046 | B47: U-0020 | C47: Apartments.com | D47: 45759 | F47: Active | G47: Yes | H47: 4910 | I47: =IF(E47="",TODAY()-D47,E47-D47) -> 374 | J47: 2BD received heavier promotion due to slower velocity
A48: LS-00047 | B48: U-0020 | C48: MLS | D48: 45762 | F48: Active | G48: No | H48: 4850 | I48: =IF(E48="",TODAY()-D48,E48-D48) -> 371 | J48: 2BD received heavier promotion due to slower velocity
A49: LS-00048 | B49: U-0020 | C49: Zillow | D49: 45880 | E49: 45914 | F49: Closed | G49: Yes | H49: 4730 | I49: =IF(E49="",TODAY()-D49,E49-D49) -> 34 | J49: 2BD received heavier promotion due to slower velocity
A50: LS-00049 | B50: U-0020 | C50: Zillow | D50: 45792 | E50: 45808 | F50: Closed | G50: No | H50: 4840 | I50: =IF(E50="",TODAY()-D50,E50-D50) -> 16 | J50: 2BD received heavier promotion due to slower velocity
A51: LS-00050 | B51: U-0021 | C51: MLS | D51: 45417 | E51: 45480 | F51: Closed | G51: No | H51: 2770 | I51: =IF(E51="",TODAY()-D51,E51-D51) -> 63 | J51: Primary student-focused listing
A52: LS-00051 | B52: U-0021 | C52: Zillow | D52: 45874 | E52: 45902 | F52: Closed | G52: Yes | H52: 2880 | I52: =IF(E52="",TODAY()-D52,E52-D52) -> 28 | J52: Primary student-focused listing
A53: LS-00052 | B53: U-0022 | C53: Apartments.com | D53: 45707 | E53: 45719 | F53: Closed | G53: No | H53: 2840 | I53: =IF(E53="",TODAY()-D53,E53-D53) -> 12 | J53: Primary student-focused listing
...

Sheet Leases
A1: lease_id | B1: unit_id | C1: lead_id | D1: lease_start_date | E1: lease_end_date | F1: signed_date | G1: monthly_rent | H1: lease_status
A2: LE-00001 | B2: U-0001 | C2: L-000001 | D2: 45936 | E2: 46296 | F2: 45911 | G2: 3050 | H2: Active
A3: LE-00002 | B3: U-0002 | C3: L-000002 | D3: 45974 | E3: 46364 | F3: 45957 | G3: 2980 | H3: Active
A4: LE-00003 | B4: U-0003 | C4: L-000003 | D4: 45843 | E4: 46233 | F4: 45804 | G4: 3060 | H4: Active
A5: LE-00004 | B5: U-0004 | C5: L-000004 | D5: 45983 | E5: 46403 | F5: 45951 | G5: 3020 | H5: Active
A6: LE-00005 | B6: U-0005 | C6: L-000005 | D6: 45819 | E6: 46209 | F6: 45794 | G6: 3060 | H6: Active
A7: LE-00006 | B7: U-0006 | C7: L-000006 | D7: 45375 | E7: 45675 | F7: 45346 | G7: 3770 | H7: Ended
A8: LE-00007 | B8: U-0006 | C8: L-000007 | D8: 45975 | E8: 46177 | F8: 45940 | G8: 3770 | H8: Notice / Ending Soon
A9: LE-00008 | B9: U-0007 | C9: L-000008 | D9: 45363 | E9: 45753 | F9: 45341 | G9: 3670 | H9: Ended
A10: LE-00009 | B10: U-0007 | C10: L-000009 | D10: 45874 | E10: 46182 | F10: 45838 | G10: 3670 | H10: Notice / Ending Soon
A11: LE-00010 | B11: U-0008 | C11: L-000010 | D11: 45937 | E11: 46357 | F11: 45898 | G11: 3900 | H11: Active
A12: LE-00011 | B12: U-0009 | C12: L-000011 | D12: 45981 | E12: 46341 | F12: 45941 | G12: 4850 | H12: Active
A13: LE-00012 | B13: U-0010 | C13: L-000012 | D13: 45541 | E13: 45961 | F13: 45504 | G13: 4570 | H13: Ended
... A95: LE-00094 | B95: U-0064 | C95: L-000094 | D95: 45784 | E95: 46204 | F95: 45757 | G95: 5260 | H95: Active
